Workbook
Name AB: 'BV ja, BV nee'!$E$7
Name AOWfranchise: Tabellen!$D$58
Name belasting: 'BV ja, BV nee'!$B$39
Name Box1DGA: 'BV ja, BV nee'!$E$31
Name Box1OND: 'BV ja, BV nee'!$B$31
Name dividendLevensonderhoud: 'BV ja, BV nee'!$E$8
Name ExclVoordeel: 'BV ja, BV nee'!$G$39
Name fiscaleClaims: 'BV ja, BV nee'!$E$44
Name invAftrek: 'BV ja, BV nee'!$B$10
Name jaar: 'BV ja, BV nee'!$B$4
Name Jaarruimte: Tabellen!$D$53
Name Jaren: 'BV ja, BV nee'!$E$5
Name KostenBV: 'BV ja, BV nee'!$E$4
Name leeftijd: 'BV ja, BV nee'!$B$5
Name loonDGA: 'BV ja, BV nee'!$E$9
Name minimaalgebruikelijkloon: Tabellen!$E$18
Name mkbvrijst: Tabellen!$D$6
Name premieBeroepspensioen: 'BV ja, BV nee'!$B$11
Name Reserveringsruimte: Tabellen!$D$54
Name StakingslijfrenteHoog: Tabellen!$D$55
Name StakingslijfrenteLaag: Tabellen!$D$57
Name StakingslijfrenteMedium: Tabellen!$D$56
Name stijgingWevab: 'BV ja, BV nee'!$B$17
Name tabelAK: Tabellen!$A$38:$C$42
Name tabelIB: Tabellen!$A$9:$D$11
Name TotaalVoordeel: 'BV ja, BV nee'!$G$44
Name versie: "v20260304"
Name vpb: 'BV ja, BV nee'!$E$34
Name vpbTarief: 'BV ja, BV nee'!$E$17
Name wevab: 'BV ja, BV nee'!$B$16
Name WinstIB: 'BV ja, BV nee'!$B$7
Name winstVoorVPB: 'BV ja, BV nee'!$E$16
Name wkr: 'BV ja, BV nee'!$E$10

Sheet BV ja, BV nee
A1: ="Berekening BV ja, BV nee op basis van één jaar - " & versie -> Berekening BV ja, BV nee op basis van één jaar - v20260304
A2: =IF(B5>65,"Dit model is niet geschikt als de AOW-leeftijd al is bereikt","")
A3: IB-onderneming | D3: BV
A4: Jaar berekening | B4: 2026 | D4: Extra kosten BV per jaar | E4: 2500
A5: Leeftijd | B5: 40 | D5: Geschat aantal jaren tot heffing box 2 | E5: =MAX(0,B6-B5) -> 27
A6: Leeftijd pensionering | B6: 67 | D6: Geschat (gemiddeld) box 2-tarief toekomst | E6: 0.245
A7: Winst vóór zelfstandigenaftrek en MKB-winstvrijstelling | B7: 200000 | D7: ="AB-claim contant "&FIXED(E6*100,2)&"%, "&E5&" jaar tegen "&FIXED(B13*100,2)&"%" -> AB-claim contant 24,50%, 27 jaar tegen 1,80% | E7: =IF(E16+B10-E8-E34=0,0,E42/(E16+B10-E8-E34)) -> 0.15134779
A8: Urencriterium van toepassing | B8: ja | D8: Dividenduitkering box 2 | E8: =WinstIB/4 -> 50000
A9: Rekening houden met startersaftrek? | B9: nee | D9: Loon DGA | E9: =MAX(WinstIB/2,minimaalgebruikelijkloon) -> 100000
A10: Investeringsaftrek | B10: 0 | D10: Vrije ruimte werkkostenregeling | E10: 2400
A11: Premie beroepspensioen | B11: 0 | D11: Investeringsaftrek | E11: =invAftrek -> 0
A12: Geschat IB-tarief banksparen, pensioen | B12: 0.4 | D12: Premie beroepspensioen | E12: =premieBeroepspensioen -> 0
A13: Disconteringsvoet fiscale claims | B13: 0.018
A14: WOZ-waarde woning | B14: 0
A15: Renteaftrek eigen woning | B15: 0
A16: WEVAB landbouwgrond | B16: 0 | D16: Winst BV, vóór VPB | E16: =WinstIB-KostenBV-loonDGA-wkr-invAftrek-premieBeroepspensioen -> 95100
A17: Stijging WEVAB per jaar | B17: 0 | D17: Gemiddeld VPB-tarief | E17: =IF(E34=0,0,E34/E16) -> 0.19
A19: Belastingberekening | D19: Belastingberekening | G19: Voordeel
A20: Winst | B20: =B7 -> 200000 | D20: Loon DGA | E20: =E9 -> 100000
A21: Af: investeringsaftrek | B21: =-B10 -> 0
A22: Af: zelfstandigenaftrek | B22: =IF(B7=0,0,IF(B8="ja",-Tabellen!D4)-IF(B9="ja",Tabellen!D5,0)) -> -1200
A23: Af: premie beroepspensioen | B23: =-B11 -> 0
A24: Af: MKB-winstvrijstelling | B24: =-mkbvrijst*SUM(B20:B23) -> -25247.6
A25: Eigenwoningforfait | B25: =IF(B14>1350000,0.35%*1350000+2.35%*(B14-1350000),0.35%*B14) -> 0 | D25: Eigenwoningforfait | E25: =B25 -> 0
A26: Af: rente eigen woning | B26: =-B15 -> 0 | D26: Af: rente eigen woning | E26: =B26 -> 0
A27: Af: Hillen-aftrek | B27: =-IF(SUM(B25:B26)>0,SUM(B25:B26),0)*71.867% -> 0 | D27: Af: Hillen-aftrek | E27: =B27 -> 0
A28: Af: bankspaarpremie | B28: 0 | D28: Af: bankspaarpremie | E28: 0
A29: Af: persoonsgebonden aftrek | B29: 0 | D29: Af: persoonsgebonden aftrek | E29: =B29 -> 0
A30: Overige inkomsten box 1 | B30: 0 | D30: Overige inkomsten box 1 | E30: 0
A31: Belastbaar inkomen box 1 | B31: =SUM(B20:B30) -> 173552.4 | D31: Belastbaar inkomen box 1 | E31: =SUM(E20:E30) -> 100000
A32: Inkomstenbelasting box 1 | B32: =MAX(0,VLOOKUP(B31,tabelIB,3)+VLOOKUP(B31,tabelIB,4)*(B31-VLOOKUP(B31,tabelIB,1))) -> 75839.568 | D32: =IF(E8>0,"Inkomstenbelasting box 1 en 2","Inkomstenbelasting box 1") -> Inkomstenbelasting box 1 en 2 | E32: =MAX(0,VLOOKUP(E31,tabelIB,3)+VLOOKUP(E31,tabelIB,4)*(E31-VLOOKUP(E31,tabelIB,1)))+E8*Tabellen!E30 -> 51681.13
A33: Bijtelling tariefcorrectie hoogste schijf | B33: =MAX(MIN(B31-B22-B24-B26-B29-Tabellen!A11,(0-B22-B24-B26-B29)),0)*(Tabellen!D11-Tabellen!E13) -> 3157.8434 | D33: =A33 -> Bijtelling tariefcorrectie hoogste schijf | E33: =MAX(MIN(E31-E26-E29-Tabellen!A11,(0-E26-E29)),0)*(Tabellen!D11-Tabellen!E13) -> 0
D34: Vennootschapsbelasting | E34: =MAX(0,IF(E16>Tabellen!E22,Tabellen!E24*Tabellen!E22+(E16-Tabellen!E22)*Tabellen!E23,E16*Tabellen!E24)) -> 18069
D35: Extra kosten BV | E35: =KostenBV -> 2500
A36: Arbeidskorting | B36: =Tabellen!D47 -> 0 | D36: Arbeidskorting | E36: =Tabellen!D51 -> 2143.0392
A37: Algemene heffingskorting | B37: =Tabellen!B47 -> 0 | D37: Algemene heffingskorting | E37: =Tabellen!B51 -> 0
A38: Bijdrage Zvw | B38: =MAX(0,MIN(Tabellen!E35,SUM(B20:B24)*Tabellen!C35)) -> 3851 | D38: Bijdrage Zvw | E38: =MAX(0,MIN(Tabellen!E35,(E20+E21)*Tabellen!C35)) -> 3851
A39: Totaal belasting excl. fiscale claims | B39: =B32+B33-B36-B37+B38 -> 82848.411 | D39: =IF(E7="","","Totaal lasten excl. fiscale claims") -> Totaal lasten excl. fiscale claims | E39: =IF(E7="","",SUM(E32:E35)-E36-E37)+E38 -> 73958.091 | G39: =IF(E7="","",B39-E39) -> 8890.3206
A40: IB-claim banksparen | B40: =-B12*(B28)/(1+B13)^(B6-B5) -> 0 | D40: Fiscale claim banksparen | E40: =(-E28*B12)/(1+B13)^(B6-B5) -> 0
A41: IB-claim beroepspensioen | B41: =(B11*B12)/(1+B13)^(B6-B5) -> 0 | D41: IB-claim beroepspensioen | E41: =B41 -> 0
...

Sheet Dividend
A1: ="Conversie salaris in dividend - " & versie -> Conversie salaris in dividend - v20260304
A3: Box 2-tarief | B3: 0.245
A4: Marginaal IB-tarief | B4: 0.495
A5: Marginaal VPB-tarief | B5: 0.19
A6: Vervanging salaris door dividend
A7: IB over salaris | B7: =B4*B6 -> 0
A8: Is netto | C8: =B6-B7 -> 0
A10: Budgettair neutraal privé; besparing in BV
A11: Benodigd dividend | B11: =C8/(100%-B3) -> 0 | C11: =" < invullen in eerste werkblad cel " & ADDRESS(ROW(dividendLevensonderhoud),COLUMN(dividendLevensonderhoud),4) -> < invullen in eerste werkblad cel E8
A12: AB-heffing | B12: =B3*B11 -> 0
A13: Is netto | C13: =B11-B12 -> 0

Sheet Ruisend
A1: ="Inbreng met geruis, voordeel lijfrenteaftrek - " & versie -> Inbreng met geruis, voordeel lijfrenteaftrek - v20260304
A3: Berekening maximaal beschikbare stakingslijfrenteaftrek
A4: Stakingslijfrente artikel 3.129 lid 2 onderdeel: a = hoog, b = medium, c = laag | B4: hoog
A5: Leeftijd ingang oudedagslijfrente | B5: ='BV ja, BV nee'!B6 -> 67
A6: Geschatte leeftijd einde levenslange lijfrenteuitkering | B6: =B5+20 -> 87
A7: Ondernemer is invalide, ja/nee | B7: nee
A8: Direct ingaande uitkeringen lijfrente stakingslijfrente ja/nee | B8: ja
A9: Maximale vrijstelling vóór imputaties | B9: =IF(B4="medium",StakingslijfrenteMedium,IF(B4="laag",StakingslijfrenteLaag,StakingslijfrenteHoog)) -> 574867
A10: Aanspraken verplichte pensioenregelingen | B10: 0
A11: Stand oudedagsreserve per 01-01 | B11: 0
A12: Lijfrentepremieaftrek vanaf 01-01-1992 t/m 31-12-2000 (2e t/m 5e tranche) | B12: 0
A13: Lijfrentepremieaftrek vanaf 01-01-2001 | B13: 0
A14: Maximale vrijstelling na imputaties | B14: =B9-B10-B11-B12-B13 -> 574867
A15: Te benutten jaarruimte en reserveringsruimte | B15: =MIN(Jaarruimte,30%*(MAX(0,(WinstIB+B17+B18-AOWfranchise))))+Reserveringsruimte -> 78342
B16: =B14+B15 -> 653209
A17: Niet geactiveerde goodwill
A18: Meerwaarde pand plus desinvesteringsbijtellingen
A19: Tekort lijfrenteaftrek | B19: =MAX(0,(B17+B18)-B16) -> 0
A20: Stakingswinst | B20: =B11+B17+B18 -> 0
A21: IB-tarief stakingswinst | B21: 0.495
A22: Belastingvoordeel MKB-winstvrijstelling stakingswinst | B22: =mkbvrijst*(B11+B17+B18)*MIN(B21,Tabellen!D10) -> 0
A23: Direct af te rekenen stille reserve en goodwill | B23: =MAX(0,B17+B18-B16) -> 0
A24: Verschuldigde IB afrekening stakingswinst | B24: =B21*B23 -> 0
A25: Direct ingaande stakingslijfrente | B25: =IF(B8="ja",MAX(0,MIN(B14,B17+B18-B15)),0) -> 0
A26: Lijfrenteaftrek jaar- en reserveringsruimte en stakingswinst (uitgestelde lijfrente) | B26: =MAX(0,(MIN(B14+B15,B17+B18)-B25)) -> 0
A27: Lijfrenteaftrek oudedagsreserve | B27: =B11 -> 0
A28: Afschrijvingstermijn goodwill | B28: 10
A29: Termijn realisatie meerwaarde pand | B29: 40
A30: VPB-tarief | B30: 0.19
A31: Disconteringspercentage contante-waardeberekening IB-claim lijfrente | B31: 0.02
A32: Periode uitstel AB-claim | B32: =B5-'BV ja, BV nee'!B5 -> 27
A33: Gemiddelde periode uitstel heffing over uitgestelde lijfrenteuitkeringen | B33: =(B5-'BV ja, BV nee'!B5)+(B6-B5)/2 -> 37
A34: Geschat IB-tarief + bijdrage Zvw over uitgestelde lijfrenteuitkeringen | B34: 0.4
A35: Contante waarde IB lijfrente jaarruimte en reserveringsruimte | B35: =MAX(0,(B26*B34)/(1+B31)^B33) -> 0
A36: Contante waarde IB lijfrente oudedagsreserve | B36: =MAX(0,(B27*B34)/(1+B31)^B33) -> 0
A37: Gemiddelde periode uitstel heffing over direct ingaande lijfrenteuitkeringen | B37: =(B6-'BV ja, BV nee'!B5)/2 -> 23.5
A38: Totaal direct ingaande lijfrente | B38: =MIN((B17+B18-B27),IF(B8="ja",B25,0)) -> 0
A39: Geschat IB-tarief direct ingaande lijfrente | B39: 0.495
A40: Contante waarde IB direct ingaande lijfrente | B40: =MAX(0,(B38*B39)/(1+B31)^B37) -> 0
A41: Totaal contante waarde IB lijfrentuitkeringen | B41: =B35+B36+B40 -> 0
...

Sheet Liqvoord
A1: ="Globaal liquiditeitsvoordeel BV 20 jaar - " & versie -> Globaal liquiditeitsvoordeel BV 20 jaar - v20260304
A3: Onderstaand volgt een overzicht van de liquideitsvoordelen van de BV. Het effect van fiscale claims wordt verwaarloosd.
A4: Rekening wordt gehouden met het (voordelige) tariefverschil tussen de VPB en de IB (box 1) en met de besparing door
A5: de oprenting van het lijfrentekapitaal.
A7: Startwaarde lijfrenteverplichting BV | D7: 0
A8: Rentepercentage oprenting lijfrentekapitaal | D8: 0.03
A9: Geschatte uitkering bij direct ingaande lijfrente | D9: =PMT(D8,88-leeftijd,-Ruisend!B38) -> 0
A10: Marginaal IB-tarief direct ingaande lijfrente | D10: 0.495
A11: Bruto rendement op liquiditeitsvoordeel BV | D11: ='BV ja, BV nee'!B13 -> 0.018
A12: VPB over rendement liquiditeitsvoordeel BV | D12: 0.19
A13: Ingangsjaar (uitgestelde) lijfrente | D13: 0
A14: Geschatte uitkering (uitgestelde) lijfrente | D14: 0
A15: Marginaal IB-tarief (uitgestelde) lijfrente | D15: 0.4
A18: ultimo | B18: ='BV ja, BV nee'!B4 -> 2026 | C18: =+B18+1 -> 2027 | D18: =+C18+1 -> 2028 | E18: =+D18+1 -> 2029 | F18: =+E18+1 -> 2030 | G18: =+F18+1 -> 2031 | H18: =+G18+1 -> 2032 | I18: =+H18+1 -> 2033 | J18: =+I18+1 -> 2034 | ... U18: =+T18+1 -> 2045
A19: IB-onderneming
A20: Winst | B20: ='BV ja, BV nee'!B7 -> 200000 | C20: =B20 -> 200000 | D20: =C20 -> 200000 | E20: =D20 -> 200000 | F20: =E20 -> 200000 | G20: =F20 -> 200000 | H20: =G20 -> 200000 | I20: =H20 -> 200000 | J20: =I20 -> 200000 | ... U20: =T20 -> 200000
A21: Overige bijtel- en aftrekposten IB | B21: =SUM('BV ja, BV nee'!B21:B30) -> -26447.6 | C21: =B21 -> -26447.6 | D21: =C21 -> -26447.6 | E21: =D21 -> -26447.6 | F21: =E21 -> -26447.6 | G21: =F21 -> -26447.6 | H21: =G21 -> -26447.6 | I21: =H21 -> -26447.6 | J21: =I21 -> -26447.6 | ... U21: =T21 -> -26447.6
A22: Inkomen box 1 | B22: =SUM(B20:B21) -> 173552.4 | C22: =SUM(C20:C21) -> 173552.4 | D22: =SUM(D20:D21) -> 173552.4 | E22: =SUM(E20:E21) -> 173552.4 | F22: =SUM(F20:F21) -> 173552.4 | G22: =SUM(G20:G21) -> 173552.4 | H22: =SUM(H20:H21) -> 173552.4 | I22: =SUM(I20:I21) -> 173552.4 | ... U22: =SUM(U20:U21) -> 173552.4
A23: IB box 1 + bijdrage ZVW | B23: =IF(B22<1,0,VLOOKUP(B22,Tabellen!$A$9:$D$11,3)+VLOOKUP(B22,Tabellen!$A$9:$D$11,4)*(B22-VLOOKUP(B22,Tabellen!$A$9:$D$11,1))+'BV ja, BV nee'!$B$33-'BV ja, BV nee'!$B$36-'BV ja, BV nee'!$B$37)+'BV ja, BV nee'!$B$38 -> 82848.411 | C23: =IF(C22<1,0,VLOOKUP(C22,Tabellen!$A$9:$D$11,3)+VLOOKUP(C22,Tabellen!$A$9:$D$11,4)*(C22-VLOOKUP(C22,Tabellen!$A$9:$D$11,1))+'BV ja, BV nee'!$B$33-'BV ja, BV nee'!$B$36-'BV ja, BV nee'!$B$37)+'BV ja, BV nee'!$B$38 -> 82848.411 | D23: =IF(D22<1,0,VLOOKUP(D22,Tabellen!$A$9:$D$11,3)+VLOOKUP(D22,Tabellen!$A$9:$D$11,4)*(D22-VLOOKUP(D22,Tabellen!$A$9:$D$11,1))+'BV ja, BV nee'!$B$33-'BV ja, BV nee'!$B$36-'BV ja, BV nee'!$B$37)+'BV ja, BV nee'!$B$38 -> 82848.411 | E23: =IF(E22<1,0,VLOOKUP(E22,Tabellen!$A$9:$D$11,3)+VLOOKUP(E22,Tabellen!$A$9:$D$11,4)*(E22-VLOOKUP(E22,Tabellen!$A$9:$D$11,1))+'BV ja, BV nee'!$B$33-'BV ja, BV nee'!$B$36-'BV ja, BV nee'!$B$37)+'BV ja, BV nee'!$B$38 -> 82848.411 | F23: =IF(F22<1,0,VLOOKUP(F22,Tabellen!$A$9:$D$11,3)+VLOOKUP(F22,Tabellen!$A$9:$D$11,4)*(F22-VLOOKUP(F22,Tabellen!$A$9:$D$11,1))+'BV ja, BV nee'!$B$33-'BV ja, BV nee'!$B$36-'BV ja, BV nee'!$B$37)+'BV ja, BV nee'!$B$38 -> 82848.411 | G23: =IF(G22<1,0,VLOOKUP(G22,Tabellen!$A$9:$D$11,3)+VLOOKUP(G22,Tabellen!$A$9:$D$11,4)*(G22-VLOOKUP(G22,Tabellen!$A$9:$D$11,1))+'BV ja, BV nee'!$B$33-'BV ja, BV nee'!$B$36-'BV ja, BV nee'!$B$37)+'BV ja, BV nee'!$B$38 -> 82848.411 | H23: =IF(H22<1,0,VLOOKUP(H22,Tabellen!$A$9:$D$11,3)+VLOOKUP(H22,Tabellen!$A$9:$D$11,4)*(H22-VLOOKUP(H22,Tabellen!$A$9:$D$11,1))+'BV ja, BV nee'!$B$33-'BV ja, BV nee'!$B$36-'BV ja, BV nee'!$B$37)+'BV ja, BV nee'!$B$38 -> 82848.411 | I23: =IF(I22<1,0,VLOOKUP(I22,Tabellen!$A$9:$D$11,3)+VLOOKUP(I22,Tabellen!$A$9:$D$11,4)*(I22-VLOOKUP(I22,Tabellen!$A$9:$D$11,1))+'BV ja, BV nee'!$B$33-'BV ja, BV nee'!$B$36-'BV ja, BV nee'!$B$37)+'BV ja, BV nee'!$B$38 -> 82848.411 | ... U23: =IF(U22<1,0,VLOOKUP(U22,Tabellen!$A$9:$D$11,3)+VLOOKUP(U22,Tabellen!$A$9:$D$11,4)*(U22-VLOOKUP(U22,Tabellen!$A$9:$D$11,1))+'BV ja, BV nee'!$B$33-'BV ja, BV nee'!$B$36-'BV ja, BV nee'!$B$37)+'BV ja, BV nee'!$B$38 -> 82848.411
A26: BV-situatie
A27: Lijfrentekapitaal na oprenting -/- uitkering | B27: =D7*(1+D8)-D9 -> 0 | C27: =B27*(1+$D$8)-$D$9-IF(C18>=$D$13,$D$14,0) -> 0 | D27: =C27*(1+$D$8)-$D$9-IF(D18>=$D$13,$D$14,0) -> 0 | E27: =D27*(1+$D$8)-$D$9-IF(E18>=$D$13,$D$14,0) -> 0 | F27: =E27*(1+$D$8)-$D$9-IF(F18>=$D$13,$D$14,0) -> 0 | G27: =F27*(1+$D$8)-$D$9-IF(G18>=$D$13,$D$14,0) -> 0 | H27: =G27*(1+$D$8)-$D$9-IF(H18>=$D$13,$D$14,0) -> 0 | I27: =H27*(1+$D$8)-$D$9-IF(I18>=$D$13,$D$14,0) -> 0 | J27: =I27*(1+$D$8)-$D$9-IF(J18>=$D$13,$D$14,0) -> 0 | ... U27: =T27*(1+$D$8)-$D$9-IF(U18>=$D$13,$D$14,0) -> 0
A28: IB salaris, dividend, bijdrage ZVW | B28: ='BV ja, BV nee'!E32-'BV ja, BV nee'!E36-'BV ja, BV nee'!E37+'BV ja, BV nee'!E33+'BV ja, BV nee'!E38 -> 53389.091 | C28: =B28 -> 53389.091 | D28: =C28 -> 53389.091 | E28: =D28 -> 53389.091 | F28: =E28 -> 53389.091 | G28: =F28 -> 53389.091 | H28: =G28 -> 53389.091 | I28: =H28 -> 53389.091 | J28: =I28 -> 53389.091 | ... U28: =T28 -> 53389.091
A29: IB over lijfrente | B29: =$D$10*$D$9+IF(B18>=$D$13,$D$14*$D$15,0) -> 0 | C29: =$D$10*$D$9+IF(C18>=$D$13,$D$14*$D$15,0) -> 0 | D29: =$D$10*$D$9+IF(D18>=$D$13,$D$14*$D$15,0) -> 0 | E29: =$D$10*$D$9+IF(E18>=$D$13,$D$14*$D$15,0) -> 0 | F29: =$D$10*$D$9+IF(F18>=$D$13,$D$14*$D$15,0) -> 0 | G29: =$D$10*$D$9+IF(G18>=$D$13,$D$14*$D$15,0) -> 0 | H29: =$D$10*$D$9+IF(H18>=$D$13,$D$14*$D$15,0) -> 0 | I29: =$D$10*$D$9+IF(I18>=$D$13,$D$14*$D$15,0) -> 0 | ... U29: =$D$10*$D$9+IF(U18>=$D$13,$D$14*$D$15,0) -> 0
A31: Winst BV vóór correcties | B31: ='BV ja, BV nee'!E16 -> 95100 | C31: =B31+C20-B20 -> 95100 | D31: =C31+D20-C20 -> 95100 | E31: =D31+E20-D20 -> 95100 | F31: =E31+F20-E20 -> 95100 | G31: =F31+G20-F20 -> 95100 | H31: =G31+H20-G20 -> 95100 | I31: =H31+I20-H20 -> 95100 | J31: =I31+J20-I20 -> 95100 | ... U31: =T31+U20-T20 -> 95100
A32: Afschrijving goodwill (10 jaar) | B32: =Ruisend!B17/10 -> 0 | C32: =B32 -> 0 | D32: =C32 -> 0 | E32: =D32 -> 0 | F32: =E32 -> 0 | G32: =F32 -> 0 | H32: =G32 -> 0 | I32: =H32 -> 0 | J32: =I32 -> 0 | K32: =J32 -> 0 | L32: 0 | M32: =L32 -> 0 | N32: =M32 -> 0 | O32: =N32 -> 0 | P32: =O32 -> 0 | Q32: =P32 -> 0 | R32: =Q32 -> 0 | S32: =R32 -> 0 | T32: =S32 -> 0 | U32: =T32 -> 0
A33: Oprenting lijfrentekapitaal | B33: =D7*D8 -> 0 | C33: =$D$8*B27 -> 0 | D33: =$D$8*C27 -> 0 | E33: =$D$8*D27 -> 0 | F33: =$D$8*E27 -> 0 | G33: =$D$8*F27 -> 0 | H33: =$D$8*G27 -> 0 | I33: =$D$8*H27 -> 0 | J33: =$D$8*I27 -> 0 | ... U33: =$D$8*T27 -> 0
A34: Winst nà correcties | B34: =B31-B32-B33 -> 95100 | C34: =C31-C32-C33 -> 95100 | D34: =D31-D32-D33 -> 95100 | E34: =E31-E32-E33 -> 95100 | F34: =F31-F32-F33 -> 95100 | G34: =G31-G32-G33 -> 95100 | H34: =H31-H32-H33 -> 95100 | I34: =I31-I32-I33 -> 95100 | ... U34: =U31-U32-U33 -> 95100
A35: VPB | B35: =MAX(0,IF(B34>Tabellen!$E$22,Tabellen!$E$24*Tabellen!$E$22+(B34-Tabellen!$E$22)*Tabellen!$E$23,B34*Tabellen!$E$24)) -> 18069 | C35: =MAX(0,IF(C34>Tabellen!$E$22,Tabellen!$E$24*Tabellen!$E$22+(C34-Tabellen!$E$22)*Tabellen!$E$23,C34*Tabellen!$E$24)) -> 18069 | D35: =MAX(0,IF(D34>Tabellen!$E$22,Tabellen!$E$24*Tabellen!$E$22+(D34-Tabellen!$E$22)*Tabellen!$E$23,D34*Tabellen!$E$24)) -> 18069 | E35: =MAX(0,IF(E34>Tabellen!$E$22,Tabellen!$E$24*Tabellen!$E$22+(E34-Tabellen!$E$22)*Tabellen!$E$23,E34*Tabellen!$E$24)) -> 18069 | F35: =MAX(0,IF(F34>Tabellen!$E$22,Tabellen!$E$24*Tabellen!$E$22+(F34-Tabellen!$E$22)*Tabellen!$E$23,F34*Tabellen!$E$24)) -> 18069 | G35: =MAX(0,IF(G34>Tabellen!$E$22,Tabellen!$E$24*Tabellen!$E$22+(G34-Tabellen!$E$22)*Tabellen!$E$23,G34*Tabellen!$E$24)) -> 18069 | H35: =MAX(0,IF(H34>Tabellen!$E$22,Tabellen!$E$24*Tabellen!$E$22+(H34-Tabellen!$E$22)*Tabellen!$E$23,H34*Tabellen!$E$24)) -> 18069 | I35: =MAX(0,IF(I34>Tabellen!$E$22,Tabellen!$E$24*Tabellen!$E$22+(I34-Tabellen!$E$22)*Tabellen!$E$23,I34*Tabellen!$E$24)) -> 18069 | ... U35: =MAX(0,IF(U34>Tabellen!$E$22,Tabellen!$E$24*Tabellen!$E$22+(U34-Tabellen!$E$22)*Tabellen!$E$23,U34*Tabellen!$E$24)) -> 18069
A36: Extra kosten BV per jaar | B36: ='BV ja, BV nee'!$E$4 -> 2500 | C36: =B36 -> 2500 | D36: =C36 -> 2500 | E36: =D36 -> 2500 | F36: =E36 -> 2500 | G36: =F36 -> 2500 | H36: =G36 -> 2500 | I36: =H36 -> 2500 | J36: =I36 -> 2500 | ... U36: =T36 -> 2500
A38: Liquiditeitsvoordeel BV jaar | B38: =B23-B28-B29-B35-B36 -> 8890.3206 | C38: =C23-C28-C29-C35-C36 -> 8890.3206 | D38: =D23-D28-D29-D35-D36 -> 8890.3206 | E38: =E23-E28-E29-E35-E36 -> 8890.3206 | F38: =F23-F28-F29-F35-F36 -> 8890.3206 | G38: =G23-G28-G29-G35-G36 -> 8890.3206 | H38: =H23-H28-H29-H35-H36 -> 8890.3206 | I38: =I23-I28-I29-I35-I36 -> 8890.3206 | ... U38: =U23-U28-U29-U35-U36 -> 8890.3206
A39: Liquiditeitsvoordeel cumulatief opgerent | B39: =B38*(1+50%*($D$11*(1-$D$12))) -> 8955.1311 | C39: =B39*(1+$D$11*(1-$D$12))+C38*(1+50%*($D$11*(1-$D$12))) -> 18040.828 | D39: =C39*(1+$D$11*(1-$D$12))+D38*(1+50%*($D$11*(1-$D$12))) -> 27258.994 | E39: =D39*(1+$D$11*(1-$D$12))+E38*(1+50%*($D$11*(1-$D$12))) -> 36611.562 | F39: =E39*(1+$D$11*(1-$D$12))+F38*(1+50%*($D$11*(1-$D$12))) -> 46100.489 | G39: =F39*(1+$D$11*(1-$D$12))+G38*(1+50%*($D$11*(1-$D$12))) -> 55727.765 | H39: =G39*(1+$D$11*(1-$D$12))+H38*(1+50%*($D$11*(1-$D$12))) -> 65495.407 | I39: =H39*(1+$D$11*(1-$D$12))+I38*(1+50%*($D$11*(1-$D$12))) -> 75405.461 | J39: =I39*(1+$D$11*(1-$D$12))+J38*(1+50%*($D$11*(1-$D$12))) -> 85460.004 | ... U39: =T39*(1+$D$11*(1-$D$12))+U38*(1+50%*($D$11*(1-$D$12))) -> 206221.27
A41: Beschikbaar voor bijv. eigenwoninglening | B41: =B20-'BV ja, BV nee'!$E$9-'BV ja, BV nee'!$E$8-Liqvoord!B35-Liqvoord!B36 -> 29431 | C41: =C20-'BV ja, BV nee'!$E$9-'BV ja, BV nee'!$E$8-Liqvoord!C35-Liqvoord!C36 -> 29431 | D41: =D20-'BV ja, BV nee'!$E$9-'BV ja, BV nee'!$E$8-Liqvoord!D35-Liqvoord!D36 -> 29431 | E41: =E20-'BV ja, BV nee'!$E$9-'BV ja, BV nee'!$E$8-Liqvoord!E35-Liqvoord!E36 -> 29431 | F41: =F20-'BV ja, BV nee'!$E$9-'BV ja, BV nee'!$E$8-Liqvoord!F35-Liqvoord!F36 -> 29431 | G41: =G20-'BV ja, BV nee'!$E$9-'BV ja, BV nee'!$E$8-Liqvoord!G35-Liqvoord!G36 -> 29431 | H41: =H20-'BV ja, BV nee'!$E$9-'BV ja, BV nee'!$E$8-Liqvoord!H35-Liqvoord!H36 -> 29431 | I41: =I20-'BV ja, BV nee'!$E$9-'BV ja, BV nee'!$E$8-Liqvoord!I35-Liqvoord!I36 -> 29431 | ... U41: =U20-'BV ja, BV nee'!$E$9-'BV ja, BV nee'!$E$8-Liqvoord!U35-Liqvoord!U36 -> 29431
A42: Cumulatief | B42: =B41 -> 29431 | C42: =B42+C41 -> 58862 | D42: =C42+D41 -> 88293 | E42: =D42+E41 -> 117724 | F42: =E42+F41 -> 147155 | G42: =F42+G41 -> 176586 | H42: =G42+H41 -> 206017 | I42: =H42+I41 -> 235448 | J42: =I42+J41 -> 264879 | ... U42: =T42+U41 -> 588620

Sheet Balans ri
A1: ="Openingsbalans ruisende inbreng - " & versie -> Openingsbalans ruisende inbreng - v20260304
A3: Zie 01-27 Modelovereenkomst inbrengbeschrijving.
A4: Balansdatum
A6: Activa
A7: Pand | B7: 0
A8: Machines | B8: 0
A9: Inventaris | B9: 0
A10: Debiteuren | B10: 0
A11: Liquiditeiten | B11: 0
A12: Transitorische posten | B12: 0
A13: Goodwill | B13: 0
A14: Overige | B14: 0
A15: Overige | B15: 0
A16: Overige | B16: 0
A17: Totaal | B17: =SUM(B7:B16) -> 0
A19: Passiva
A20: Aandelenkapitaal, agio | B20: =B29-SUM(B21:B28) -> 0
A21: Bank | B21: 0
A22: Transitorische posten | B22: 0
A23: Lijfrenteverplichting | B23: 0
A24: Creditering aandeelhouder | B24: 0
A25: Overige | B25: 0
A26: Overige | B26: 0
A27: Overige | B27: 0
A28: Belastinglatentie | B28: 0
A29: Totaal | B29: =B17 -> 0

Sheet Balans gi 
A1: ="Openingsbalans geruisloze inbreng - " & versie -> Openingsbalans geruisloze inbreng - v20260304
A3: Slotbalans IB-onderneming na eventuele onttrekking activa
A4: Activa | B4: fiscaal | C4: werkelijk | D4: meerwaarde | E4: latentie % | F4: latentie (€)
A5: Pand | B5: 0 | C5: 0 | D5: =C5-B5 -> 0 | E5: 0.1 | F5: =E5*D5 -> 0
A6: Machines | B6: 0 | C6: =B6 -> 0 | D6: =C6-B6 -> 0 | E6: 0.2 | F6: =E6*D6 -> 0
A7: Inventaris | B7: 0 | C7: =B7 -> 0 | D7: =C7-B7 -> 0 | E7: 0.2 | F7: =E7*D7 -> 0
A8: Debiteuren | B8: 0 | C8: =B8 -> 0
A9: Liquiditeiten | B9: 0 | C9: =B9 -> 0
A10: Transitorische posten | B10: 0 | C10: =B10 -> 0
A11: Goodwill | B11: 0 | C11: 0 | D11: =C11-B11 -> 0 | E11: 0.15 | F11: =E11*D11 -> 0
A12: Overige | B12: 0 | C12: =B12 -> 0 | D12: =C12-B12 -> 0 | E12: 0.2 | F12: =E12*D12 -> 0
A13: Totaal | B13: =SUM(B5:B12) -> 0 | C13: =SUM(C5:C12) -> 0 | D13: =SUM(D5:D12) -> 0 | F13: =SUM(F5:F12) -> 0
A15: Passiva
A16: Fiscaal vermogen exclusief oudedagsreserve | B16: =B13-SUM(B17:B22) -> 0 | C16: =C13-SUM(C17:C22) -> 0
A17: Oudedagsreserve | B17: 0 | C17: =B17 -> 0
A18: Herinvesteringsreserve | B18: 0 | C18: =B18 -> 0 | E18: 0.1 | F18: =C18*E18 -> 0
A19: Egalisatiereserve | B19: 0 | C19: =B19 -> 0
A20: Bank | B20: 0 | C20: =B20 -> 0
A21: Transitorische posten | B21: 0 | C21: =B21 -> 0
A22: Overige schulden | B22: 0 | C22: =B22 -> 0
A23: Totaal | B23: =SUM(B16:B22) -> 0 | C23: =SUM(C16:C22) -> 0
A25: Te bedingen lijfrente BV in verband met oudedagsreserve | B25: 0
A27: Op overgangstijdstip verschuldigde IB etc. | B27: 0
A28: Creditering (maximaal 5% gestorte kapitaal, maximaal € 30.000) | C28: =IF(B28>D28,"Let op maximum!","Maximum") -> Maximum | D28: =MIN(30000,5%*C46) -> 0
A29: Totale creditering | B29: =B27+B28 -> 0
A31: Zie modelovereenkomst 01-27 Model inbrengbeschrijving.
A33: Openingsbalans BV
A34: Activa | B34: fiscaal | C34: commercieel
A35: Pand | B35: =B5 -> 0 | C35: =C5 -> 0
A36: Machines | B36: =B6 -> 0 | C36: =C6 -> 0
A37: Inventaris | B37: =B7 -> 0 | C37: =C7 -> 0
A38: Debiteuren | B38: =B8 -> 0 | C38: =C8 -> 0
A39: Liquiditeiten | B39: =B9 -> 0 | C39: =C9 -> 0
A40: Transitorische posten | B40: =B10 -> 0 | C40: =C10 -> 0
A41: Goodwill | B41: =B11 -> 0 | C41: =C11 -> 0
A42: Overige | B42: =B12 -> 0 | C42: =C12 -> 0
A43: Totaal | B43: =SUM(B35:B42) -> 0 | C43: =SUM(C35:C42) -> 0
A45: Passiva
A46: Aandelenkapitaal, agio | C46: =C43-SUM(C49:C55) -> 0
A47: Fiscaal vermogen (= verkrijgingsprijs aanmerkelijk belang) | B47: =B43-SUM(B48:B54) -> 0
...

Sheet Art14
A1: ="Art. 14 VPB-fusie na geruisloze inbreng vanuit twee personal holdings - " & versie -> Art. 14 VPB-fusie na geruisloze inbreng vanuit twee personal holdings - v20260304
A3: Firmant A | B3: A
A4: Firmant B | B4: B
A6: Van firma naar werkmaatschappij
A7: ="Kapitaalrekening "&B3&" in firma" -> Kapitaalrekening A in firma | B7: 0
A8: ="Kapitaalrekening "&B4&" in firma" -> Kapitaalrekening B in firma | B8: 0
A9: Goodwill en stille reserves | B9: 0
A10: VPB-latentie | B10: 0
A11: Totaal | B11: =SUM(B7:B9)-B10 -> 0
A12: ="Winstaandeel "&B3 -> Winstaandeel A | B12: 0.5
A13: ="Winstaandeel "&B4 -> Winstaandeel B | B13: =1-B12 -> 0.5
A14: ="Kapitaal + creditering PH "&B3 -> Kapitaal + creditering PH A | B14: =B7+B12*B9-B12*B10 -> 0
A15: ="Kapitaal + creditering PH "&B4 -> Kapitaal + creditering PH B | B15: =B8+B13*B9-B13*B10 -> 0
A16: ="Creditering werkmij PH "&B3 -> Creditering werkmij PH A | B16: 0
A17: ="Creditering werkmij PH "&B4 -> Creditering werkmij PH B | B17: 0
A18: ="Deelneming PH "&B3 -> Deelneming PH A | B18: =B14-B16 -> 0
A19: ="Deelneming PH "&B4 -> Deelneming PH B | B19: =B15-B17 -> 0
A20: Totaal aandelenkapitaal | B20: =B18+B19 -> 0
A21: ="Gewoon aandelenkapitaal PH "&B3 -> Gewoon aandelenkapitaal PH A | B21: =MIN(B18,IF(B19<B20,B19*B12/B13,B18)) -> 0 | C21: =IF((B21+B22)>0,B21/(B21+B22),0) -> 0
A22: ="Gewoon aandelenkapitaal PH "&B4 -> Gewoon aandelenkapitaal PH B | B22: =B13/B12*B21 -> 0 | C22: =IF((B21+B22)>0,B22/(B21+B22),0) -> 0
A23: ="Preferent aandelenkapitaal PH "&B3 -> Preferent aandelenkapitaal PH A | B23: =MAX(0,B18-B21) -> 0
A24: ="Preferent aandelenkapitaal PH "&B4 -> Preferent aandelenkapitaal PH B | B24: =MAX(0,B19-B22) -> 0
A25: Totaal aandelenkapitaal | B25: =SUM(B21:B24) -> 0 | D25: ="Balans personal holding "&B3 -> Balans personal holding A
D26: Deelneming werkmaatschappij | E26: =B21+B23 -> 0
A27: Toelaatbare creditering werkmij | B27: =MIN(4500,1%*(B14+B15)) -> 0 | D27: Creditering werkmaatschappij | E27: =B16 -> 0
A28: Binnen de norm? | B28: =IF(B16+B17<=B27,"ja","nee") -> ja | D28: Totaal | E28: =SUM(E26:E27) -> 0
A30: Commerciële balans werkmaatschappij | D30: Aandelenkapitaal/agio | E30: =E26+E27-E31-E32 -> 0
A31: Activa | B31: =SUM(B7:B9) -> 0 | D31: Creditering in PH | E31: 0
D32: Lijfrenteverplichting | E32: 0
A33: Aandelenkapitaal | B33: =B21+B22+B23+B24 -> 0 | D33: Totaal | E33: =SUM(E30:E32) -> 0
A34: Creditering | B34: =B16+B17 -> 0
A35: VPB-latentie | B35: =B10 -> 0 | D35: ="Balans personal holding "&B4 -> Balans personal holding B
A36: Totaal | B36: =SUM(B33:B35) -> 0 | D36: Deelneming werkmaatschappij | E36: =B22+B24 -> 0
D37: Creditering werkmaatschappij | E37: =B17 -> 0
A38: Fiscale balans werkmaatschappij | D38: Totaal | E38: =SUM(E36:E37) -> 0
A39: Activa | B39: =B7+B8 -> 0
D40: Aandelenkapitaal/agio | E40: =E36+E37-E41-E42 -> 0
A41: Vermogen | B41: =B39-B42 -> 0 | D41: Creditering in PH | E41: 0
A42: Creditering | B42: =B34 -> 0 | D42: Lijfrenteverplichting | E42: 0
A43: Totaal | B43: =B41+B42 -> 0 | D43: Totaal | E43: =SUM(E40:E42) -> 0

Sheet Firma-BV
A1: ="Firma met de BV - " & versie -> Firma met de BV - v20260304
A3: Jaar berekening | C3: =jaar -> 2026
A4: Leeftijd ondernemer | C4: ='BV ja, BV nee'!B5 -> 40
A5: Leeftijd pensionering | C5: ='BV ja, BV nee'!B6 -> 67
A6: Extra kosten firma met de BV per jaar | C6: 2000
A7: Winstaandeel IB-onderneming na extra kosten firma | C7: ='BV ja, BV nee'!E9*1.2 -> 120000
A8: Urencriterium van toepassing | C8: ='BV ja, BV nee'!B8 -> ja
A9: Rekening houden met startersaftrek? | C9: ='BV ja, BV nee'!B9 -> nee
A11: Investeringsaftrek | C11: ='BV ja, BV nee'!B10 -> 0
A12: Premie beroepspensioen | C12: ='BV ja, BV nee'!B11 -> 0
A13: Geschat IB-tarief lijfrente, pensioen | C13: ='BV ja, BV nee'!B12 -> 0.4
A14: Disconteringsvoet fiscale claims | C14: ='BV ja, BV nee'!B13 -> 0.018
A15: WOZ-waarde woning | C15: ='BV ja, BV nee'!B14 -> 0
A16: Renteaftrek eigen woning | C16: ='BV ja, BV nee'!B15 -> 0
A18: Winst BV na extra kosten firma | C18: =(WinstIB-C6)-C7 -> 78000
A19: Salaris bij BV (in principe 0 ex art. 12a lid 4 Wet LB 1964) | C19: 0
A20: Geschat aantal jaren tot heffing box 2 | C20: =MAX(0,C5-C4) -> 27
A21: Dividend | C21: =dividendLevensonderhoud -> 50000
A22: Box 2-tarief over dividend | C22: 0.245
A24: Belastingberekening IB
A25: Winst | C25: =C7 -> 120000
A26: Af: investeringsaftrek | C26: =-C11 -> 0
A27: Af: zelfstandigenaftrek | C27: =IF(C7=0,0,IF(C8="ja",-Tabellen!D4)-IF(C9="ja",Tabellen!D5,0)) -> -1200
A28: Af: premie beroepspensioen | C28: =-C12 -> 0
A29: Af: MKB-winstvrijstelling | C29: =-mkbvrijst*(C7-C11-C12+C27) -> -15087.6
A30: Eigenwoningforfait | C30: ='BV ja, BV nee'!B25 -> 0
A31: Af: rente eigen woning | C31: =-C16 -> 0
A32: Af: banksparen | C32: 0
A33: Af: persoonsgebonden aftrek | C33: 0
A34: Overige inkomsten box 1 | C34: 0
A35: Belastbaar inkomen box 1 | C35: =SUM(C25:C34) -> 103712.4
A37: Inkomstenbelasting box 1 | C37: =MAX(0,VLOOKUP(C35,tabelIB,3)+VLOOKUP(C35,tabelIB,4)*(C35-VLOOKUP(C35,tabelIB,1))) -> 41268.768
A38: Bijtelling tariefcorrectie hoogste schijf | C38: =MAX(MIN(C35-C27-C29-C31-C33-Tabellen!A11,(0-C27-C29-C31-C33)),0)*(Tabellen!D11-Tabellen!E13) -> 1944.7394
A39: Arbeidskorting | C39: =-(VLOOKUP((C25+C26+C34),tabelAK,3)+((C25+C26+C34)-VLOOKUP((C25+C26+C34),tabelAK,1))*VLOOKUP((C25+C26+C34),tabelAK,2)) -> -841.0392
A40: Algemene heffingskorting | C40: =-ROUNDUP(IF((C35+C21)>29736,MAX(3115-((C35+C21)-29736)*6.398%,0),3115),0) -> 0
A41: Bijdrage Zvw | C41: =MAX(0,MIN(Tabellen!E35,SUM(C25:C29)*Tabellen!C35)) -> 3851
A42: IB-claim banksparen | C42: =-(C10*C13)/(1+C14)^(C5-C4) -> 0
A43: IB-claim beroepspensioen | C43: =(C12*C13)/(1+C14)^(C5-C4) -> 0
A45: Extra kosten firma met de BV | C45: =C6 -> 2000
A46: VPB | C46: =MAX(0,IF(C18>Tabellen!E22,Tabellen!E24*Tabellen!E22+(C18-Tabellen!E22)*Tabellen!E23,C18*Tabellen!E24)) -> 14820
...

Sheet Tabellen
A1: ="Tabellen - " & versie -> Tabellen - v20260304
D3: =jaar -> 2026
A4: Zelfstandigenaftrek | D4: 1200
A5: Startersaftrek | D5: 2123
A6: MKB-winstvrijstelling | D6: 0.127
A8: ="IB-tarief box 1 tot AOW-leeftijd " & jaar -> IB-tarief box 1 tot AOW-leeftijd 2026
A9: 0 | B9: 38883 | D9: 0.3575
A10: =B9 -> 38883 | B10: 78426 | C10: =TRUNC(D9*B9) -> 13900 | D10: 0.3756
A11: =B10 -> 78426 | C11: =TRUNC(C10+(B10-A10)*D10) -> 28752 | D11: 0.495
A13: ="Tarief waartegen aftrekposten in " & jaar & " maximaal kunnen worden verrekend" -> Tarief waartegen aftrekposten in 2026 maximaal kunnen worden verrekend | E13: =D10 -> 0.3756
A15: Wat de heffingskortingen betreft wordt alleen rekening gehouden met de arbeidskorting
A16: en de algemene heffingskorting.
A18: Minimaal gebruikelijk loon | E18: 58000
A21: VPB-tarieven | E21: =jaar -> 2026
A22: Tariefopstapje | E22: 200000
A23: VPB-tarief hoog | E23: 0.258
A24: VPB-tarief laag | E24: 0.19
A26: IB-tarieven box 2 | E26: =jaar -> 2026
A27: ="Lage box 2-tarief " & jaar -> Lage box 2-tarief 2026 | E27: 0.245
A28: ="Tariefopstapje " & jaar -> Tariefopstapje 2026 | E28: 68843
A29: Hoge box 2-tarief 2026 | E29: 0.31
A30: ="Gemiddelde box 2-tarief dividend " & jaar -> Gemiddelde box 2-tarief dividend 2026 | E30: =IF(dividendLevensonderhoud=0,0,(IF(dividendLevensonderhoud=0,0,(MAX(0,dividendLevensonderhoud-E28)*E29+MIN(E28,dividendLevensonderhoud)*E27))/dividendLevensonderhoud)) -> 0.245
A33: ="Bijdrage Zvw " & jaar -> Bijdrage Zvw 2026
A34: Maximum bijdrage-inkomen | C34: 79409
A35: Tarief ondernemers/dga's | C35: 0.0485 | D35: maximaal > | E35: =TRUNC(C34*C35) -> 3851
A37: ="Tabel arbeidskorting " & jaar -> Tabel arbeidskorting 2026
A38: 0 | B38: 0.08324 | C38: 0
A39: 11965 | B39: 0.31009 | C39: 996
A40: 25845 | B40: 0.0195 | C40: 5300
A41: 45592 | B41: -0.0651 | C41: 5685
A42: 132920 | C42: 0
A44: Algemene heffingskorting | D44: Arbeidskorting | E44: Arbeidskorting grondslag
A45: IB
A47: =jaar -> 2026 | B47: =ROUNDUP(IF(Box1OND>29736,MAX(3115-(Box1OND-29736)*6.398%,0),3115),0) -> 0 | D47: =VLOOKUP(E47,tabelAK,3)+(E47-VLOOKUP(E47,tabelAK,1))*VLOOKUP(E47,tabelAK,2) -> 0 | E47: ='BV ja, BV nee'!B20+'BV ja, BV nee'!B21+'BV ja, BV nee'!B23+'BV ja, BV nee'!B30 -> 200000
A49: BV
A51: =jaar -> 2026 | B51: =IF((Box1DGA+dividendLevensonderhoud)>29736,MAX(3115-((Box1DGA+dividendLevensonderhoud)-29736)*6.398%,0),3115) -> 0 | D51: =VLOOKUP(E51,tabelAK,3)+(E51-VLOOKUP(E51,tabelAK,1))*VLOOKUP(E51,tabelAK,2) -> 2143.0392 | E51: ='BV ja, BV nee'!E20+'BV ja, BV nee'!B21+'BV ja, BV nee'!E30 -> 100000
A53: Maximaal jaarruimte | D53: =ROUNDUP((137800-AOWfranchise)*30%,0) -> 35589
A54: Maximaal reserveringsruimte | D54: 42753
A55: Stakingslijfrenteaftrek hoog | D55: 574867
A56: Stakingslijfrenteaftrek medium | D56: 287445
...

Sheet Uitleg
B1: ="Uitleg - " & versie -> Uitleg - v20260304
B3: BV ja, BV nee
B4: Dit tabblad berekent het voordeel van de BV ten opzichte van de IB-onderneming.
B5: ="Op regel " & ROW(belasting) & " wordt alleen naar de directe heffingen gekeken. Bij de IB-onderneming is dat de IB" -> Op regel 39 wordt alleen naar de directe heffingen gekeken. Bij de IB-onderneming is dat de IB
B6: over de winst en de overige inkomsten en bij het BV-scenario de VPB en de IB over het salaris.
B8: Wat de heffingskortingen betreft, wordt alleen met de arbeidskorting en de algemene heffing-
B9: korting rekening gehouden. Deze kortingen zijn inkomensafhankelijk en werken daarom in de
B10: meeste gevallen gunstig uit voor de BV.
B12: ="Op regel " & ROW(fiscaleClaims) & " worden ook de fiscale claims (banksparen, pensioen en aanmerkelijk belang) meegenomen." -> Op regel 44 worden ook de fiscale claims (banksparen, pensioen en aanmerkelijk belang) meegenomen.
B13: De fiscale claims worden in aanmerking genomen voor de contante waarde. De contante
B14: waarde wordt berekend op basis van de disconteringsvoet en het aantal jaren tot pensioen.
B16: Het voordeel van uitstel van heffing over beroepspensioen, banksparen en aanmerkelijk belang
B17: wordt tot uitdrukking gebracht in de disconteringsvoet. Dit is het netto rendement dat op het
B18: vermogen wordt behaald.
B20: ="Bij de BV wordt er over de landbouwvrijstelling wel AB-claim opgebouwd (cel " &ADDRESS(ROW(wevab),COLUMN(wevab),4) &" en cel " &ADDRESS(ROW(stijgingWevab),COLUMN(stijgingWevab),4) & ")" -> Bij de BV wordt er over de landbouwvrijstelling wel AB-claim opgebouwd (cel B16 en cel B17)
B22: Voor het DGA-salaris doet het model de suggestie van 50% van de winst met als minimum het
B23: bedrag van art. 12a Wet LB 1964 (gebruikelijk loon).
B24: Voor het jaarlijkse dividend is het voorstel van het rekenmodel 1/4 van de winst.
B26: ="De werkkostenregeling is een pluspunt voor de BV. In cel " & ADDRESS(ROW(wkr),COLUMN(wkr),4) & " kan in de meeste gevallen " -> De werkkostenregeling is een pluspunt voor de BV. In cel E10 kan in de meeste gevallen
B27: € 2.400 worden ingevuld (de doelmatigheidsgrens waarmee de fiscus ongetoetst akkoord gaat).
B29: Het model kan rekening houden met een verschil in (accountants)kosten tussen een persoonlijke
B30: onderneming en een BV. Deze worden meegenomen bij de winstberekening waardoor een
B31: VPB-besparing optreedt, alsmede een besparing op de IB-claim. Zie adviestekst dga-109 voor een
B32: schatting. Oprichtingkosten uitsmeren over aantal jaren.
B34: Het model is niet geschikt voor de ondernemers die de AOW-leeftijd reeds hebben bereikt (voor
B35: wie lagere IB-tarieven gelden).
B37: De verlaging van het tarief (in de hoogste schijf) waartegen aftrekposten maximaal kunnen
B38: ="worden verrekend, bedraagt in " & jaar & " " & FIXED(Tabellen!E13*100,2) & "%. Dit betekent een tariefcorrectie" -> worden verrekend, bedraagt in 2026 37,56%. Dit betekent een tariefcorrectie
B39: ="in de hoogste schijf van " & FIXED((Tabellen!D11-Tabellen!E13)*100,2) & "%." -> in de hoogste schijf van 11,94%.
B41: Dividend
B42: Minimaliseer het salaris binnen de grens van art. 12a Wet LB 1964 (gebruikelijk loon). Het gecombineerde
B43: VPB/IB-tarief is lager dan het IB-tarief (vermeerderd met de bijdrage Zvw). Dit tabblad is een hulp-
B44: middel om de voor de DGA in privé budgettair neutrale conversie van salaris in dividend te berekenen.
B46: Ruisend
B47: Geruisloze inbreng is het meest eenvoudig. Het is de aangewezen weg bij zeer hoge meer-
B48: waarden. Als de meerwaarden (grotendeels) binnen de grenzen van de lijfrenteaftrek kunnen
B49: worden afgewikkeld, kan ruisende inbreng voordelig zijn. Ruisende inbreng biedt de volgende
B50: voordelen:
B51: - MKB-winstvrijstelling over stakingswinst;
B52: - afschrijving over goodwill;
...

Sheet Release notes
B1: ="Release notes - " & versie -> Release notes - v20260304
B3: v20260304
B4: - | C4: Het absolute maximumbedrag van de creditering bij geruisloze inbreng is verhoogd naar € 30.000 (vierde
C5: standaardvoorwaarde; tab Balans gi)
B7: v20260110
B8: - | C8: Update definitieve cijfers 2026
B9: - | C9: Enkele visuele en tekstuele aanpassingen
B11: v20261118
B12: - | C12: De eerste versie van het 2026-model, met de t/m 18-11-2025 bekendgemaakte (voorlopige) cijfers
B13: - | C13: Diverse tekstuele aanpassingen ten opzichte van rekenmodel 05-01a BV 2025

Sheet Copyright
B1: ="Copyright - " & versie -> Copyright - v20260304
B3: © Wolters Kluwer Nederland. Alle (auteurs-)rechten op dit document berusten bij Wolters Kluwer Nederland B.V. of haar licentiegevers en worden uitdrukkelijk voorbehouden.
B4: Tekst- en datamining niet toegestaan. Kijk voor meer informatie over de diensten van Wolters Kluwer op www.wolterskluwer.nl.
